Workbook
Name ChungChi: [1]ViTriLamViec!#REF!
Name ChungChi: [1]ViTriLamViec!#REF!
Name ChungChi: [1]ViTriLamViec!#REF!
Name ChungChi: [1]ViTriLamViec!#REF!
Name ChuyenNghanh: [1]DM_NganhDT!#REF!
Name ChuyenNghanh: [1]DM_NganhDT!#REF!
Name ChuyenNghanh: [1]DM_NganhDT!#REF!
Name ChuyenNghanh: [1]DM_NganhDT!#REF!
Name CoSoDaoTao: #REF!
Name CoSoDaoTao: #REF!
Name CoSoDaoTao: #REF!
Name CoSoDaoTao: #REF!
Name CoSoDaoTao_: #REF!
Name DanhMucPhong: #REF!
Name DanhMucPhong: #REF!
Name DanhMucPhong: #REF!
Name DanhMucPhong: #REF!
Name DanToc: [1]DanToc!#REF!
Name DanToc: [1]DanToc!#REF!
Name DanToc: [1]DanToc!#REF!
Name DanToc: [1]DanToc!#REF!

Sheet Ke hoach giảng dạy CNTT
A1: TRƯỜNG ĐẠI HỌC VĂN LANG
A2: KHOA CÔNG NGHỆ THÔNG TIN
A4: KẾ HOẠCH ĐÀO TẠO NGÀNH CÔNG NGHỆ THÔNG TIN - KHÓA 30 | N4: =SUM(N9:N100) -> 126
E6: 2 | F6: 4 | G6: 5 | H6: 6 | I6: 7 | J6: 8 | K6: 9 | L6: 10 | M6: 11
A7: TT | B7: Phân bổ học kỳ | C7: Năm Thứ | D7: Mã học phần | E7: Tên học phần (Tiếng Việt) | F7: Số tín chỉ | G7: Số tiết/giờ | K7: Bắt buộc/Tự chọn | L7: ĐK tiên quyết | M7: ĐK học trước | N7: Số TC/ HK | O7: Ghi chú
G8: LT | H8: TH | I8: ĐA | J8: TT
A9: HK241 1 | B9: 1 | C9: 1 | D9: 71ENG110013 | E9: =VLOOKUP($D9,'Khung_CTĐT_CNTT_K30 (2024)'!$B$10:$L$96,'Ke hoach giảng dạy CNTT'!E$6,0) -> Anh văn 1 (AV1) | F9: =VLOOKUP($D9,'Khung_CTĐT_CNTT_K30 (2024)'!$B$10:$L$96,'Ke hoach giảng dạy CNTT'!F$6,0) -> 3 | G9: =VLOOKUP($D9,'Khung_CTĐT_CNTT_K30 (2024)'!$B$10:$L$96,'Ke hoach giảng dạy CNTT'!G$6,0) -> 30 | H9: =VLOOKUP($D9,'Khung_CTĐT_CNTT_K30 (2024)'!$B$10:$L$96,'Ke hoach giảng dạy CNTT'!H$6,0) -> 30 | I9: =VLOOKUP($D9,'Khung_CTĐT_CNTT_K30 (2024)'!$B$10:$L$96,'Ke hoach giảng dạy CNTT'!I$6,0) -> 0 | J9: =VLOOKUP($D9,'Khung_CTĐT_CNTT_K30 (2024)'!$B$10:$L$96,'Ke hoach giảng dạy CNTT'!J$6,0) -> 0 | K9: =VLOOKUP($D9,'Khung_CTĐT_CNTT_K30 (2024)'!$B$10:$L$96,'Ke hoach giảng dạy CNTT'!K$6,0) -> BB | L9: =VLOOKUP($D9,'Khung_CTĐT_CNTT_K30 (2024)'!$B$10:$L$96,'Ke hoach giảng dạy CNTT'!L$6,0) -> [71ENG010012]Anh văn dự bị (AV0) | M9: =VLOOKUP($D9,'Khung_CTĐT_CNTT_K30 (2024)'!$B$10:$L$96,'Ke hoach giảng dạy CNTT'!M$6,0) -> Không | N9: =SUM(F9:F12) -> 12 | P9: 12 | Q9: 1
B10: 1 | C10: 1 | D10: 71ITBS10103 | E10: =VLOOKUP($D10,'Khung_CTĐT_CNTT_K30 (2024)'!$B$10:$L$96,'Ke hoach giảng dạy CNTT'!E$6,0) -> Nhập môn Công nghệ thông tin | F10: =VLOOKUP($D10,'Khung_CTĐT_CNTT_K30 (2024)'!$B$10:$L$96,'Ke hoach giảng dạy CNTT'!F$6,0) -> 3 | G10: =VLOOKUP($D10,'Khung_CTĐT_CNTT_K30 (2024)'!$B$10:$L$96,'Ke hoach giảng dạy CNTT'!G$6,0) -> 30 | H10: =VLOOKUP($D10,'Khung_CTĐT_CNTT_K30 (2024)'!$B$10:$L$96,'Ke hoach giảng dạy CNTT'!H$6,0) -> 30 | I10: =VLOOKUP($D10,'Khung_CTĐT_CNTT_K30 (2024)'!$B$10:$L$96,'Ke hoach giảng dạy CNTT'!I$6,0) -> 0 | J10: =VLOOKUP($D10,'Khung_CTĐT_CNTT_K30 (2024)'!$B$10:$L$96,'Ke hoach giảng dạy CNTT'!J$6,0) -> 0 | K10: =VLOOKUP($D10,'Khung_CTĐT_CNTT_K30 (2024)'!$B$10:$L$96,'Ke hoach giảng dạy CNTT'!K$6,0) -> BB | L10: =VLOOKUP($D10,'Khung_CTĐT_CNTT_K30 (2024)'!$B$10:$L$96,'Ke hoach giảng dạy CNTT'!L$6,0) -> Không | M10: =VLOOKUP($D10,'Khung_CTĐT_CNTT_K30 (2024)'!$B$10:$L$96,'Ke hoach giảng dạy CNTT'!M$6,0) -> Không | Q10: =Q9 -> 1 | R10: =IFERROR(VLOOKUP(D10,$D$9:D9,1,0),"")
B11: 1 | C11: 1 | D11: 71ITBS10203 | E11: =VLOOKUP($D11,'Khung_CTĐT_CNTT_K30 (2024)'!$B$10:$L$96,'Ke hoach giảng dạy CNTT'!E$6,0) -> Cơ sở lập trình | F11: =VLOOKUP($D11,'Khung_CTĐT_CNTT_K30 (2024)'!$B$10:$L$96,'Ke hoach giảng dạy CNTT'!F$6,0) -> 3 | G11: =VLOOKUP($D11,'Khung_CTĐT_CNTT_K30 (2024)'!$B$10:$L$96,'Ke hoach giảng dạy CNTT'!G$6,0) -> 30 | H11: =VLOOKUP($D11,'Khung_CTĐT_CNTT_K30 (2024)'!$B$10:$L$96,'Ke hoach giảng dạy CNTT'!H$6,0) -> 30 | I11: =VLOOKUP($D11,'Khung_CTĐT_CNTT_K30 (2024)'!$B$10:$L$96,'Ke hoach giảng dạy CNTT'!I$6,0) -> 0 | J11: =VLOOKUP($D11,'Khung_CTĐT_CNTT_K30 (2024)'!$B$10:$L$96,'Ke hoach giảng dạy CNTT'!J$6,0) -> 0 | K11: =VLOOKUP($D11,'Khung_CTĐT_CNTT_K30 (2024)'!$B$10:$L$96,'Ke hoach giảng dạy CNTT'!K$6,0) -> BB | L11: =VLOOKUP($D11,'Khung_CTĐT_CNTT_K30 (2024)'!$B$10:$L$96,'Ke hoach giảng dạy CNTT'!L$6,0) -> Không | M11: =VLOOKUP($D11,'Khung_CTĐT_CNTT_K30 (2024)'!$B$10:$L$96,'Ke hoach giảng dạy CNTT'!M$6,0) -> Không | Q11: =Q10 -> 1 | R11: =IFERROR(VLOOKUP(D11,$D$9:D10,1,0),"")
B12: 1 | C12: 1 | D12: 71SSK110023 | E12: =VLOOKUP($D12,'Khung_CTĐT_CNTT_K30 (2024)'!$B$10:$L$96,'Ke hoach giảng dạy CNTT'!E$6,0) -> Kỹ năng công dân toàn cầu | F12: =VLOOKUP($D12,'Khung_CTĐT_CNTT_K30 (2024)'!$B$10:$L$96,'Ke hoach giảng dạy CNTT'!F$6,0) -> 3 | G12: =VLOOKUP($D12,'Khung_CTĐT_CNTT_K30 (2024)'!$B$10:$L$96,'Ke hoach giảng dạy CNTT'!G$6,0) -> 45 | H12: =VLOOKUP($D12,'Khung_CTĐT_CNTT_K30 (2024)'!$B$10:$L$96,'Ke hoach giảng dạy CNTT'!H$6,0) -> 0 | I12: =VLOOKUP($D12,'Khung_CTĐT_CNTT_K30 (2024)'!$B$10:$L$96,'Ke hoach giảng dạy CNTT'!I$6,0) -> 0 | J12: =VLOOKUP($D12,'Khung_CTĐT_CNTT_K30 (2024)'!$B$10:$L$96,'Ke hoach giảng dạy CNTT'!J$6,0) -> 0 | K12: =VLOOKUP($D12,'Khung_CTĐT_CNTT_K30 (2024)'!$B$10:$L$96,'Ke hoach giảng dạy CNTT'!K$6,0) -> BB | L12: =VLOOKUP($D12,'Khung_CTĐT_CNTT_K30 (2024)'!$B$10:$L$96,'Ke hoach giảng dạy CNTT'!L$6,0) -> Không | M12: =VLOOKUP($D12,'Khung_CTĐT_CNTT_K30 (2024)'!$B$10:$L$96,'Ke hoach giảng dạy CNTT'!M$6,0) -> Không | Q12: =Q11 -> 1 | R12: =IFERROR(VLOOKUP(D12,$D$9:D11,1,0),"")
B13: 1 | C13: 1 | D13: 71NAD110013 | E13: =VLOOKUP($D13,'Khung_CTĐT_CNTT_K30 (2024)'!$B$10:$L$96,'Ke hoach giảng dạy CNTT'!E$6,0) -> GDQP1: Đường lối QP và AN của ĐCSVN | F13: =VLOOKUP($D13,'Khung_CTĐT_CNTT_K30 (2024)'!$B$10:$L$96,'Ke hoach giảng dạy CNTT'!F$6,0) -> 3 | G13: =VLOOKUP($D13,'Khung_CTĐT_CNTT_K30 (2024)'!$B$10:$L$96,'Ke hoach giảng dạy CNTT'!G$6,0) -> 0 | H13: =VLOOKUP($D13,'Khung_CTĐT_CNTT_K30 (2024)'!$B$10:$L$96,'Ke hoach giảng dạy CNTT'!H$6,0) -> 0 | I13: =VLOOKUP($D13,'Khung_CTĐT_CNTT_K30 (2024)'!$B$10:$L$96,'Ke hoach giảng dạy CNTT'!I$6,0) -> 0 | J13: =VLOOKUP($D13,'Khung_CTĐT_CNTT_K30 (2024)'!$B$10:$L$96,'Ke hoach giảng dạy CNTT'!J$6,0) -> 0 | K13: =VLOOKUP($D13,'Khung_CTĐT_CNTT_K30 (2024)'!$B$10:$L$96,'Ke hoach giảng dạy CNTT'!K$6,0) -> BB | L13: =VLOOKUP($D13,'Khung_CTĐT_CNTT_K30 (2024)'!$B$10:$L$96,'Ke hoach giảng dạy CNTT'!L$6,0) | M13: =VLOOKUP($D13,'Khung_CTĐT_CNTT_K30 (2024)'!$B$10:$L$96,'Ke hoach giảng dạy CNTT'!M$6,0) | Q13: =Q12 -> 1 | R13: =IFERROR(VLOOKUP(D13,$D$9:D12,1,0),"")
B14: 1 | C14: 1 | D14: 71NAD210022 | E14: =VLOOKUP($D14,'Khung_CTĐT_CNTT_K30 (2024)'!$B$10:$L$96,'Ke hoach giảng dạy CNTT'!E$6,0) -> GDQP2: Công tác quốc phòng và an ninh | F14: =VLOOKUP($D14,'Khung_CTĐT_CNTT_K30 (2024)'!$B$10:$L$96,'Ke hoach giảng dạy CNTT'!F$6,0) -> 2 | G14: =VLOOKUP($D14,'Khung_CTĐT_CNTT_K30 (2024)'!$B$10:$L$96,'Ke hoach giảng dạy CNTT'!G$6,0) -> 0 | H14: =VLOOKUP($D14,'Khung_CTĐT_CNTT_K30 (2024)'!$B$10:$L$96,'Ke hoach giảng dạy CNTT'!H$6,0) -> 0 | I14: =VLOOKUP($D14,'Khung_CTĐT_CNTT_K30 (2024)'!$B$10:$L$96,'Ke hoach giảng dạy CNTT'!I$6,0) -> 0 | J14: =VLOOKUP($D14,'Khung_CTĐT_CNTT_K30 (2024)'!$B$10:$L$96,'Ke hoach giảng dạy CNTT'!J$6,0) -> 0 | K14: =VLOOKUP($D14,'Khung_CTĐT_CNTT_K30 (2024)'!$B$10:$L$96,'Ke hoach giảng dạy CNTT'!K$6,0) -> BB | L14: =VLOOKUP($D14,'Khung_CTĐT_CNTT_K30 (2024)'!$B$10:$L$96,'Ke hoach giảng dạy CNTT'!L$6,0) | M14: =VLOOKUP($D14,'Khung_CTĐT_CNTT_K30 (2024)'!$B$10:$L$96,'Ke hoach giảng dạy CNTT'!M$6,0) | Q14: =Q13 -> 1 | R14: =IFERROR(VLOOKUP(D14,$D$9:D13,1,0),"")
B15: 1 | C15: 1 | D15: 71NAD310032 | E15: =VLOOKUP($D15,'Khung_CTĐT_CNTT_K30 (2024)'!$B$10:$L$96,'Ke hoach giảng dạy CNTT'!E$6,0) -> GDQP3: Quân sự chung | F15: =VLOOKUP($D15,'Khung_CTĐT_CNTT_K30 (2024)'!$B$10:$L$96,'Ke hoach giảng dạy CNTT'!F$6,0) -> 2 | G15: =VLOOKUP($D15,'Khung_CTĐT_CNTT_K30 (2024)'!$B$10:$L$96,'Ke hoach giảng dạy CNTT'!G$6,0) -> 0 | H15: =VLOOKUP($D15,'Khung_CTĐT_CNTT_K30 (2024)'!$B$10:$L$96,'Ke hoach giảng dạy CNTT'!H$6,0) -> 0 | I15: =VLOOKUP($D15,'Khung_CTĐT_CNTT_K30 (2024)'!$B$10:$L$96,'Ke hoach giảng dạy CNTT'!I$6,0) -> 0 | J15: =VLOOKUP($D15,'Khung_CTĐT_CNTT_K30 (2024)'!$B$10:$L$96,'Ke hoach giảng dạy CNTT'!J$6,0) -> 0 | K15: =VLOOKUP($D15,'Khung_CTĐT_CNTT_K30 (2024)'!$B$10:$L$96,'Ke hoach giảng dạy CNTT'!K$6,0) -> BB | L15: =VLOOKUP($D15,'Khung_CTĐT_CNTT_K30 (2024)'!$B$10:$L$96,'Ke hoach giảng dạy CNTT'!L$6,0) | M15: =VLOOKUP($D15,'Khung_CTĐT_CNTT_K30 (2024)'!$B$10:$L$96,'Ke hoach giảng dạy CNTT'!M$6,0) | Q15: =Q14 -> 1 | R15: =IFERROR(VLOOKUP(D15,$D$9:D14,1,0),"")
B16: 1 | C16: 1 | D16: 71NAD410044 | E16: =VLOOKUP($D16,'Khung_CTĐT_CNTT_K30 (2024)'!$B$10:$L$96,'Ke hoach giảng dạy CNTT'!E$6,0) -> GDQP4: Kỹ thuật chiến đấu bộ binh và chiến thuật | F16: =VLOOKUP($D16,'Khung_CTĐT_CNTT_K30 (2024)'!$B$10:$L$96,'Ke hoach giảng dạy CNTT'!F$6,0) -> 4 | G16: =VLOOKUP($D16,'Khung_CTĐT_CNTT_K30 (2024)'!$B$10:$L$96,'Ke hoach giảng dạy CNTT'!G$6,0) -> 0 | H16: =VLOOKUP($D16,'Khung_CTĐT_CNTT_K30 (2024)'!$B$10:$L$96,'Ke hoach giảng dạy CNTT'!H$6,0) -> 0 | I16: =VLOOKUP($D16,'Khung_CTĐT_CNTT_K30 (2024)'!$B$10:$L$96,'Ke hoach giảng dạy CNTT'!I$6,0) -> 0 | J16: =VLOOKUP($D16,'Khung_CTĐT_CNTT_K30 (2024)'!$B$10:$L$96,'Ke hoach giảng dạy CNTT'!J$6,0) -> 0 | K16: =VLOOKUP($D16,'Khung_CTĐT_CNTT_K30 (2024)'!$B$10:$L$96,'Ke hoach giảng dạy CNTT'!K$6,0) -> BB | L16: =VLOOKUP($D16,'Khung_CTĐT_CNTT_K30 (2024)'!$B$10:$L$96,'Ke hoach giảng dạy CNTT'!L$6,0) | M16: =VLOOKUP($D16,'Khung_CTĐT_CNTT_K30 (2024)'!$B$10:$L$96,'Ke hoach giảng dạy CNTT'!M$6,0) | Q16: =Q15 -> 1 | R16: =IFERROR(VLOOKUP(D16,$D$9:D15,1,0),"")
Q17: =Q16 -> 1 | R17: =IFERROR(VLOOKUP(D17,$D$9:D16,1,0),"")
A18: HK242 2 | B18: 2 | C18: 1 | D18: 71POLP10013 | E18: =VLOOKUP($D18,'Khung_CTĐT_CNTT_K30 (2024)'!$B$10:$L$96,'Ke hoach giảng dạy CNTT'!E$6,0) -> Triết học Mác-Lênin | F18: =VLOOKUP($D18,'Khung_CTĐT_CNTT_K30 (2024)'!$B$10:$L$96,'Ke hoach giảng dạy CNTT'!F$6,0) -> 3 | G18: =VLOOKUP($D18,'Khung_CTĐT_CNTT_K30 (2024)'!$B$10:$L$96,'Ke hoach giảng dạy CNTT'!G$6,0) -> 45 | H18: =VLOOKUP($D18,'Khung_CTĐT_CNTT_K30 (2024)'!$B$10:$L$96,'Ke hoach giảng dạy CNTT'!H$6,0) -> 0 | I18: =VLOOKUP($D18,'Khung_CTĐT_CNTT_K30 (2024)'!$B$10:$L$96,'Ke hoach giảng dạy CNTT'!I$6,0) -> 0 | J18: =VLOOKUP($D18,'Khung_CTĐT_CNTT_K30 (2024)'!$B$10:$L$96,'Ke hoach giảng dạy CNTT'!J$6,0) -> 0 | K18: =VLOOKUP($D18,'Khung_CTĐT_CNTT_K30 (2024)'!$B$10:$L$96,'Ke hoach giảng dạy CNTT'!K$6,0) -> BB | L18: =VLOOKUP($D18,'Khung_CTĐT_CNTT_K30 (2024)'!$B$10:$L$96,'Ke hoach giảng dạy CNTT'!L$6,0) -> Không | M18: =VLOOKUP($D18,'Khung_CTĐT_CNTT_K30 (2024)'!$B$10:$L$96,'Ke hoach giảng dạy CNTT'!M$6,0) -> Không | N18: =SUM(F18:F22) -> 16 | P18: =P9+N18 -> 28 | Q18: 2 | R18: =IFERROR(VLOOKUP(D18,$D$9:D17,1,0),"")
B19: 2 | C19: 1 | D19: 71ENG210023 | E19: =VLOOKUP($D19,'Khung_CTĐT_CNTT_K30 (2024)'!$B$10:$L$96,'Ke hoach giảng dạy CNTT'!E$6,0) -> Anh văn 2 (AV2) | F19: =VLOOKUP($D19,'Khung_CTĐT_CNTT_K30 (2024)'!$B$10:$L$96,'Ke hoach giảng dạy CNTT'!F$6,0) -> 3 | G19: =VLOOKUP($D19,'Khung_CTĐT_CNTT_K30 (2024)'!$B$10:$L$96,'Ke hoach giảng dạy CNTT'!G$6,0) -> 30 | H19: =VLOOKUP($D19,'Khung_CTĐT_CNTT_K30 (2024)'!$B$10:$L$96,'Ke hoach giảng dạy CNTT'!H$6,0) -> 30 | I19: =VLOOKUP($D19,'Khung_CTĐT_CNTT_K30 (2024)'!$B$10:$L$96,'Ke hoach giảng dạy CNTT'!I$6,0) -> 0 | J19: =VLOOKUP($D19,'Khung_CTĐT_CNTT_K30 (2024)'!$B$10:$L$96,'Ke hoach giảng dạy CNTT'!J$6,0) -> 0 | K19: =VLOOKUP($D19,'Khung_CTĐT_CNTT_K30 (2024)'!$B$10:$L$96,'Ke hoach giảng dạy CNTT'!K$6,0) -> BB | L19: =VLOOKUP($D19,'Khung_CTĐT_CNTT_K30 (2024)'!$B$10:$L$96,'Ke hoach giảng dạy CNTT'!L$6,0) -> [71ENG110013]Anh văn 1 (AV1) | M19: =VLOOKUP($D19,'Khung_CTĐT_CNTT_K30 (2024)'!$B$10:$L$96,'Ke hoach giảng dạy CNTT'!M$6,0) -> Không | Q19: =Q18 -> 2 | R19: =IFERROR(VLOOKUP(D19,$D$9:D18,1,0),"")
B20: 2 | C20: 1 | D20: 71ITMA10104 | E20: =VLOOKUP($D20,'Khung_CTĐT_CNTT_K30 (2024)'!$B$10:$L$96,'Ke hoach giảng dạy CNTT'!E$6,0) -> Toán cao cấp và ứng dụng | F20: =VLOOKUP($D20,'Khung_CTĐT_CNTT_K30 (2024)'!$B$10:$L$96,'Ke hoach giảng dạy CNTT'!F$6,0) -> 4 | G20: =VLOOKUP($D20,'Khung_CTĐT_CNTT_K30 (2024)'!$B$10:$L$96,'Ke hoach giảng dạy CNTT'!G$6,0) -> 45 | H20: =VLOOKUP($D20,'Khung_CTĐT_CNTT_K30 (2024)'!$B$10:$L$96,'Ke hoach giảng dạy CNTT'!H$6,0) -> 30 | I20: =VLOOKUP($D20,'Khung_CTĐT_CNTT_K30 (2024)'!$B$10:$L$96,'Ke hoach giảng dạy CNTT'!I$6,0) -> 0 | J20: =VLOOKUP($D20,'Khung_CTĐT_CNTT_K30 (2024)'!$B$10:$L$96,'Ke hoach giảng dạy CNTT'!J$6,0) -> 0 | K20: =VLOOKUP($D20,'Khung_CTĐT_CNTT_K30 (2024)'!$B$10:$L$96,'Ke hoach giảng dạy CNTT'!K$6,0) -> BB | L20: =VLOOKUP($D20,'Khung_CTĐT_CNTT_K30 (2024)'!$B$10:$L$96,'Ke hoach giảng dạy CNTT'!L$6,0) -> Không | M20: =VLOOKUP($D20,'Khung_CTĐT_CNTT_K30 (2024)'!$B$10:$L$96,'Ke hoach giảng dạy CNTT'!M$6,0) -> Không | Q20: =Q19 -> 2 | R20: =IFERROR(VLOOKUP(D20,$D$9:D19,1,0),"")
B21: 2 | C21: 1 | D21: 71ITNW30103 | E21: =VLOOKUP($D21,'Khung_CTĐT_CNTT_K30 (2024)'!$B$10:$L$96,'Ke hoach giảng dạy CNTT'!E$6,0) -> Nhập môn Mạng máy tính và điện toán đám mây | F21: =VLOOKUP($D21,'Khung_CTĐT_CNTT_K30 (2024)'!$B$10:$L$96,'Ke hoach giảng dạy CNTT'!F$6,0) -> 3 | G21: =VLOOKUP($D21,'Khung_CTĐT_CNTT_K30 (2024)'!$B$10:$L$96,'Ke hoach giảng dạy CNTT'!G$6,0) -> 30 | H21: =VLOOKUP($D21,'Khung_CTĐT_CNTT_K30 (2024)'!$B$10:$L$96,'Ke hoach giảng dạy CNTT'!H$6,0) -> 30 | I21: =VLOOKUP($D21,'Khung_CTĐT_CNTT_K30 (2024)'!$B$10:$L$96,'Ke hoach giảng dạy CNTT'!I$6,0) -> 0 | J21: =VLOOKUP($D21,'Khung_CTĐT_CNTT_K30 (2024)'!$B$10:$L$96,'Ke hoach giảng dạy CNTT'!J$6,0) -> 0 | K21: =VLOOKUP($D21,'Khung_CTĐT_CNTT_K30 (2024)'!$B$10:$L$96,'Ke hoach giảng dạy CNTT'!K$6,0) -> BB | L21: =VLOOKUP($D21,'Khung_CTĐT_CNTT_K30 (2024)'!$B$10:$L$96,'Ke hoach giảng dạy CNTT'!L$6,0) -> Không | M21: =VLOOKUP($D21,'Khung_CTĐT_CNTT_K30 (2024)'!$B$10:$L$96,'Ke hoach giảng dạy CNTT'!M$6,0) -> Không | Q21: =Q20 -> 2 | R21: =IFERROR(VLOOKUP(D21,$D$9:D20,1,0),"")
B22: 2 | C22: 1 | D22: 71ITSE30103 | E22: =VLOOKUP($D22,'Khung_CTĐT_CNTT_K30 (2024)'!$B$10:$L$96,'Ke hoach giảng dạy CNTT'!E$6,0) -> Kỹ thuật lập trình | F22: =VLOOKUP($D22,'Khung_CTĐT_CNTT_K30 (2024)'!$B$10:$L$96,'Ke hoach giảng dạy CNTT'!F$6,0) -> 3 | G22: =VLOOKUP($D22,'Khung_CTĐT_CNTT_K30 (2024)'!$B$10:$L$96,'Ke hoach giảng dạy CNTT'!G$6,0) -> 30 | H22: =VLOOKUP($D22,'Khung_CTĐT_CNTT_K30 (2024)'!$B$10:$L$96,'Ke hoach giảng dạy CNTT'!H$6,0) -> 30 | I22: =VLOOKUP($D22,'Khung_CTĐT_CNTT_K30 (2024)'!$B$10:$L$96,'Ke hoach giảng dạy CNTT'!I$6,0) -> 0 | J22: =VLOOKUP($D22,'Khung_CTĐT_CNTT_K30 (2024)'!$B$10:$L$96,'Ke hoach giảng dạy CNTT'!J$6,0) -> 0 | K22: =VLOOKUP($D22,'Khung_CTĐT_CNTT_K30 (2024)'!$B$10:$L$96,'Ke hoach giảng dạy CNTT'!K$6,0) -> BB | L22: =VLOOKUP($D22,'Khung_CTĐT_CNTT_K30 (2024)'!$B$10:$L$96,'Ke hoach giảng dạy CNTT'!L$6,0) -> Không | M22: =VLOOKUP($D22,'Khung_CTĐT_CNTT_K30 (2024)'!$B$10:$L$96,'Ke hoach giảng dạy CNTT'!M$6,0) -> [71ITBS10203]Cơ sở lập trình | Q22: =Q21 -> 2 | R22: =IFERROR(VLOOKUP(D22,$D$9:D21,1,0),"")
Q23: =Q22 -> 2 | R23: =IFERROR(VLOOKUP(D23,$D$9:D22,1,0),"")
A24: HK243 3 | B24: 3 | C24: 1 | D24: 71POLE10022 | E24: =VLOOKUP($D24,'Khung_CTĐT_CNTT_K30 (2024)'!$B$10:$L$96,'Ke hoach giảng dạy CNTT'!E$6,0) -> Kinh tế chính trị Mác-Lênin | F24: =VLOOKUP($D24,'Khung_CTĐT_CNTT_K30 (2024)'!$B$10:$L$96,'Ke hoach giảng dạy CNTT'!F$6,0) -> 2 | G24: =VLOOKUP($D24,'Khung_CTĐT_CNTT_K30 (2024)'!$B$10:$L$96,'Ke hoach giảng dạy CNTT'!G$6,0) -> 30 | H24: =VLOOKUP($D24,'Khung_CTĐT_CNTT_K30 (2024)'!$B$10:$L$96,'Ke hoach giảng dạy CNTT'!H$6,0) -> 0 | I24: =VLOOKUP($D24,'Khung_CTĐT_CNTT_K30 (2024)'!$B$10:$L$96,'Ke hoach giảng dạy CNTT'!I$6,0) -> 0 | J24: =VLOOKUP($D24,'Khung_CTĐT_CNTT_K30 (2024)'!$B$10:$L$96,'Ke hoach giảng dạy CNTT'!J$6,0) -> 0 | K24: =VLOOKUP($D24,'Khung_CTĐT_CNTT_K30 (2024)'!$B$10:$L$96,'Ke hoach giảng dạy CNTT'!K$6,0) -> BB | L24: =VLOOKUP($D24,'Khung_CTĐT_CNTT_K30 (2024)'!$B$10:$L$96,'Ke hoach giảng dạy CNTT'!L$6,0) -> Không | M24: =VLOOKUP($D24,'Khung_CTĐT_CNTT_K30 (2024)'!$B$10:$L$96,'Ke hoach giảng dạy CNTT'!M$6,0) -> [71POLP10013]Triết học Mác-Lênin | N24: =SUM(F24:F28) -> 14 | P24: =P18+N24 -> 42 | Q24: 3 | R24: =IFERROR(VLOOKUP(D24,$D$9:D23,1,0),"")
B25: 3 | C25: 1 | D25: 71ENG310033 | E25: =VLOOKUP($D25,'Khung_CTĐT_CNTT_K30 (2024)'!$B$10:$L$96,'Ke hoach giảng dạy CNTT'!E$6,0) -> Anh văn 3 (AV3) | F25: =VLOOKUP($D25,'Khung_CTĐT_CNTT_K30 (2024)'!$B$10:$L$96,'Ke hoach giảng dạy CNTT'!F$6,0) -> 3 | G25: =VLOOKUP($D25,'Khung_CTĐT_CNTT_K30 (2024)'!$B$10:$L$96,'Ke hoach giảng dạy CNTT'!G$6,0) -> 30 | H25: =VLOOKUP($D25,'Khung_CTĐT_CNTT_K30 (2024)'!$B$10:$L$96,'Ke hoach giảng dạy CNTT'!H$6,0) -> 30 | I25: =VLOOKUP($D25,'Khung_CTĐT_CNTT_K30 (2024)'!$B$10:$L$96,'Ke hoach giảng dạy CNTT'!I$6,0) -> 0 | J25: =VLOOKUP($D25,'Khung_CTĐT_CNTT_K30 (2024)'!$B$10:$L$96,'Ke hoach giảng dạy CNTT'!J$6,0) -> 0 | K25: =VLOOKUP($D25,'Khung_CTĐT_CNTT_K30 (2024)'!$B$10:$L$96,'Ke hoach giảng dạy CNTT'!K$6,0) -> BB | L25: =VLOOKUP($D25,'Khung_CTĐT_CNTT_K30 (2024)'!$B$10:$L$96,'Ke hoach giảng dạy CNTT'!L$6,0) -> [71ENG210023]Anh văn 2 (AV2) | M25: =VLOOKUP($D25,'Khung_CTĐT_CNTT_K30 (2024)'!$B$10:$L$96,'Ke hoach giảng dạy CNTT'!M$6,0) -> Không | Q25: =Q24 -> 3 | R25: =IFERROR(VLOOKUP(D25,$D$9:D24,1,0),"")
B26: 3 | C26: 1 | D26: 71ITIS30103 | E26: =VLOOKUP($D26,'Khung_CTĐT_CNTT_K30 (2024)'!$B$10:$L$96,'Ke hoach giảng dạy CNTT'!E$6,0) -> Cơ sở dữ liệu | F26: =VLOOKUP($D26,'Khung_CTĐT_CNTT_K30 (2024)'!$B$10:$L$96,'Ke hoach giảng dạy CNTT'!F$6,0) -> 3 | G26: =VLOOKUP($D26,'Khung_CTĐT_CNTT_K30 (2024)'!$B$10:$L$96,'Ke hoach giảng dạy CNTT'!G$6,0) -> 30 | H26: =VLOOKUP($D26,'Khung_CTĐT_CNTT_K30 (2024)'!$B$10:$L$96,'Ke hoach giảng dạy CNTT'!H$6,0) -> 30 | I26: =VLOOKUP($D26,'Khung_CTĐT_CNTT_K30 (2024)'!$B$10:$L$96,'Ke hoach giảng dạy CNTT'!I$6,0) -> 0 | J26: =VLOOKUP($D26,'Khung_CTĐT_CNTT_K30 (2024)'!$B$10:$L$96,'Ke hoach giảng dạy CNTT'!J$6,0) -> 0 | K26: =VLOOKUP($D26,'Khung_CTĐT_CNTT_K30 (2024)'!$B$10:$L$96,'Ke hoach giảng dạy CNTT'!K$6,0) -> BB | L26: =VLOOKUP($D26,'Khung_CTĐT_CNTT_K30 (2024)'!$B$10:$L$96,'Ke hoach giảng dạy CNTT'!L$6,0) -> Không | M26: =VLOOKUP($D26,'Khung_CTĐT_CNTT_K30 (2024)'!$B$10:$L$96,'Ke hoach giảng dạy CNTT'!M$6,0) -> Không | Q26: =Q25 -> 3 | R26: =IFERROR(VLOOKUP(D26,$D$9:D25,1,0),"")
B27: 3 | C27: 1 | D27: 71ITSE30303 | E27: =VLOOKUP($D27,'Khung_CTĐT_CNTT_K30 (2024)'!$B$10:$L$96,'Ke hoach giảng dạy CNTT'!E$6,0) -> Cấu trúc dữ liệu và giải thuật | F27: =VLOOKUP($D27,'Khung_CTĐT_CNTT_K30 (2024)'!$B$10:$L$96,'Ke hoach giảng dạy CNTT'!F$6,0) -> 3 | G27: =VLOOKUP($D27,'Khung_CTĐT_CNTT_K30 (2024)'!$B$10:$L$96,'Ke hoach giảng dạy CNTT'!G$6,0) -> 30 | H27: =VLOOKUP($D27,'Khung_CTĐT_CNTT_K30 (2024)'!$B$10:$L$96,'Ke hoach giảng dạy CNTT'!H$6,0) -> 30 | I27: =VLOOKUP($D27,'Khung_CTĐT_CNTT_K30 (2024)'!$B$10:$L$96,'Ke hoach giảng dạy CNTT'!I$6,0) -> 0 | J27: =VLOOKUP($D27,'Khung_CTĐT_CNTT_K30 (2024)'!$B$10:$L$96,'Ke hoach giảng dạy CNTT'!J$6,0) -> 0 | K27: =VLOOKUP($D27,'Khung_CTĐT_CNTT_K30 (2024)'!$B$10:$L$96,'Ke hoach giảng dạy CNTT'!K$6,0) -> BB | L27: =VLOOKUP($D27,'Khung_CTĐT_CNTT_K30 (2024)'!$B$10:$L$96,'Ke hoach giảng dạy CNTT'!L$6,0) -> Không | M27: =VLOOKUP($D27,'Khung_CTĐT_CNTT_K30 (2024)'!$B$10:$L$96,'Ke hoach giảng dạy CNTT'!M$6,0) -> [71ITBS10203]Cơ sở lập trình | Q27: =Q26 -> 3 | R27: =IFERROR(VLOOKUP(D27,$D$9:D26,1,0),"")
B28: 3 | C28: 1 | D28: 71MATL10053 | E28: =VLOOKUP($D28,'Khung_CTĐT_CNTT_K30 (2024)'!$B$10:$L$96,'Ke hoach giảng dạy CNTT'!E$6,0) -> Đại số tuyến tính và ứng dụng | F28: =VLOOKUP($D28,'Khung_CTĐT_CNTT_K30 (2024)'!$B$10:$L$96,'Ke hoach giảng dạy CNTT'!F$6,0) -> 3 | G28: =VLOOKUP($D28,'Khung_CTĐT_CNTT_K30 (2024)'!$B$10:$L$96,'Ke hoach giảng dạy CNTT'!G$6,0) -> 30 | H28: =VLOOKUP($D28,'Khung_CTĐT_CNTT_K30 (2024)'!$B$10:$L$96,'Ke hoach giảng dạy CNTT'!H$6,0) -> 30 | I28: =VLOOKUP($D28,'Khung_CTĐT_CNTT_K30 (2024)'!$B$10:$L$96,'Ke hoach giảng dạy CNTT'!I$6,0) -> 0 | J28: =VLOOKUP($D28,'Khung_CTĐT_CNTT_K30 (2024)'!$B$10:$L$96,'Ke hoach giảng dạy CNTT'!J$6,0) -> 0 | K28: =VLOOKUP($D28,'Khung_CTĐT_CNTT_K30 (2024)'!$B$10:$L$96,'Ke hoach giảng dạy CNTT'!K$6,0) -> BB | L28: =VLOOKUP($D28,'Khung_CTĐT_CNTT_K30 (2024)'!$B$10:$L$96,'Ke hoach giảng dạy CNTT'!L$6,0) -> Không | M28: =VLOOKUP($D28,'Khung_CTĐT_CNTT_K30 (2024)'!$B$10:$L$96,'Ke hoach giảng dạy CNTT'!M$6,0) -> Không | Q28: =Q27 -> 3 | R28: =IFERROR(VLOOKUP(D28,$D$9:D27,1,0),"")
Q29: =Q28 -> 3 | R29: =IFERROR(VLOOKUP(D29,$D$9:D28,1,0),"")
A30: HK251 4 | B30: 1 | C30: 2 | N30: =SUM(F30:F34) -> 13 | P30: =P24+N30 -> 55 | Q30: 4 | R30: =IFERROR(VLOOKUP(D30,$D$9:D29,1,0),"")
B31: 1 | C31: 2 | D31: 71ENG410043 | E31: =VLOOKUP($D31,'Khung_CTĐT_CNTT_K30 (2024)'!$B$10:$L$96,'Ke hoach giảng dạy CNTT'!E$6,0) -> Anh văn 4 (AV4) | F31: =VLOOKUP($D31,'Khung_CTĐT_CNTT_K30 (2024)'!$B$10:$L$96,'Ke hoach giảng dạy CNTT'!F$6,0) -> 3 | G31: =VLOOKUP($D31,'Khung_CTĐT_CNTT_K30 (2024)'!$B$10:$L$96,'Ke hoach giảng dạy CNTT'!G$6,0) -> 30 | H31: =VLOOKUP($D31,'Khung_CTĐT_CNTT_K30 (2024)'!$B$10:$L$96,'Ke hoach giảng dạy CNTT'!H$6,0) -> 30 | I31: =VLOOKUP($D31,'Khung_CTĐT_CNTT_K30 (2024)'!$B$10:$L$96,'Ke hoach giảng dạy CNTT'!I$6,0) -> 0 | J31: =VLOOKUP($D31,'Khung_CTĐT_CNTT_K30 (2024)'!$B$10:$L$96,'Ke hoach giảng dạy CNTT'!J$6,0) -> 0 | K31: =VLOOKUP($D31,'Khung_CTĐT_CNTT_K30 (2024)'!$B$10:$L$96,'Ke hoach giảng dạy CNTT'!K$6,0) -> BB | L31: =VLOOKUP($D31,'Khung_CTĐT_CNTT_K30 (2024)'!$B$10:$L$96,'Ke hoach giảng dạy CNTT'!L$6,0) -> [71ENG310033]Anh văn 3 (AV3) | M31: =VLOOKUP($D31,'Khung_CTĐT_CNTT_K30 (2024)'!$B$10:$L$96,'Ke hoach giảng dạy CNTT'!M$6,0) -> Không | Q31: =Q30 -> 4 | R31: =IFERROR(VLOOKUP(D31,$D$9:D30,1,0),"")
B32: 1 | C32: 2 | D32: 71ITMA10403 | E32: =VLOOKUP($D32,'Khung_CTĐT_CNTT_K30 (2024)'!$B$10:$L$96,'Ke hoach giảng dạy CNTT'!E$6,0) -> Toán rời rạc | F32: =VLOOKUP($D32,'Khung_CTĐT_CNTT_K30 (2024)'!$B$10:$L$96,'Ke hoach giảng dạy CNTT'!F$6,0) -> 4 | G32: =VLOOKUP($D32,'Khung_CTĐT_CNTT_K30 (2024)'!$B$10:$L$96,'Ke hoach giảng dạy CNTT'!G$6,0) -> 45 | H32: =VLOOKUP($D32,'Khung_CTĐT_CNTT_K30 (2024)'!$B$10:$L$96,'Ke hoach giảng dạy CNTT'!H$6,0) -> 30 | I32: =VLOOKUP($D32,'Khung_CTĐT_CNTT_K30 (2024)'!$B$10:$L$96,'Ke hoach giảng dạy CNTT'!I$6,0) -> 0 | J32: =VLOOKUP($D32,'Khung_CTĐT_CNTT_K30 (2024)'!$B$10:$L$96,'Ke hoach giảng dạy CNTT'!J$6,0) -> 0 | K32: =VLOOKUP($D32,'Khung_CTĐT_CNTT_K30 (2024)'!$B$10:$L$96,'Ke hoach giảng dạy CNTT'!K$6,0) -> BB | L32: =VLOOKUP($D32,'Khung_CTĐT_CNTT_K30 (2024)'!$B$10:$L$96,'Ke hoach giảng dạy CNTT'!L$6,0) -> Không | M32: =VLOOKUP($D32,'Khung_CTĐT_CNTT_K30 (2024)'!$B$10:$L$96,'Ke hoach giảng dạy CNTT'!M$6,0) -> [71ITMA10104]Toán cao cấp và ứng dụng | Q32: =Q31 -> 4 | R32: =IFERROR(VLOOKUP(D32,$D$9:D31,1,0),"")
B33: 1 | C33: 2 | D33: 71ITSE30203 | E33: =VLOOKUP($D33,'Khung_CTĐT_CNTT_K30 (2024)'!$B$10:$L$96,'Ke hoach giảng dạy CNTT'!E$6,0) -> Lập trình hướng đối tượng | F33: =VLOOKUP($D33,'Khung_CTĐT_CNTT_K30 (2024)'!$B$10:$L$96,'Ke hoach giảng dạy CNTT'!F$6,0) -> 3 | G33: =VLOOKUP($D33,'Khung_CTĐT_CNTT_K30 (2024)'!$B$10:$L$96,'Ke hoach giảng dạy CNTT'!G$6,0) -> 30 | H33: =VLOOKUP($D33,'Khung_CTĐT_CNTT_K30 (2024)'!$B$10:$L$96,'Ke hoach giảng dạy CNTT'!H$6,0) -> 30 | I33: =VLOOKUP($D33,'Khung_CTĐT_CNTT_K30 (2024)'!$B$10:$L$96,'Ke hoach giảng dạy CNTT'!I$6,0) -> 0 | J33: =VLOOKUP($D33,'Khung_CTĐT_CNTT_K30 (2024)'!$B$10:$L$96,'Ke hoach giảng dạy CNTT'!J$6,0) -> 0 | K33: =VLOOKUP($D33,'Khung_CTĐT_CNTT_K30 (2024)'!$B$10:$L$96,'Ke hoach giảng dạy CNTT'!K$6,0) -> BB | L33: =VLOOKUP($D33,'Khung_CTĐT_CNTT_K30 (2024)'!$B$10:$L$96,'Ke hoach giảng dạy CNTT'!L$6,0) -> Không | M33: =VLOOKUP($D33,'Khung_CTĐT_CNTT_K30 (2024)'!$B$10:$L$96,'Ke hoach giảng dạy CNTT'!M$6,0) -> [71ITBS10203]Cơ sở lập trình | Q33: =Q32 -> 4 | R33: =IFERROR(VLOOKUP(D33,$D$9:D32,1,0),"")
B34: 1 | C34: 2 | D34: 71ITSE30503 | E34: =VLOOKUP($D34,'Khung_CTĐT_CNTT_K30 (2024)'!$B$10:$L$96,'Ke hoach giảng dạy CNTT'!E$6,0) -> Lập trình ứng dụng Web | F34: =VLOOKUP($D34,'Khung_CTĐT_CNTT_K30 (2024)'!$B$10:$L$96,'Ke hoach giảng dạy CNTT'!F$6,0) -> 3 | G34: =VLOOKUP($D34,'Khung_CTĐT_CNTT_K30 (2024)'!$B$10:$L$96,'Ke hoach giảng dạy CNTT'!G$6,0) -> 30 | H34: =VLOOKUP($D34,'Khung_CTĐT_CNTT_K30 (2024)'!$B$10:$L$96,'Ke hoach giảng dạy CNTT'!H$6,0) -> 30 | I34: =VLOOKUP($D34,'Khung_CTĐT_CNTT_K30 (2024)'!$B$10:$L$96,'Ke hoach giảng dạy CNTT'!I$6,0) -> 0 | J34: =VLOOKUP($D34,'Khung_CTĐT_CNTT_K30 (2024)'!$B$10:$L$96,'Ke hoach giảng dạy CNTT'!J$6,0) -> 0 | K34: =VLOOKUP($D34,'Khung_CTĐT_CNTT_K30 (2024)'!$B$10:$L$96,'Ke hoach giảng dạy CNTT'!K$6,0) -> BB | L34: =VLOOKUP($D34,'Khung_CTĐT_CNTT_K30 (2024)'!$B$10:$L$96,'Ke hoach giảng dạy CNTT'!L$6,0) -> Không | M34: =VLOOKUP($D34,'Khung_CTĐT_CNTT_K30 (2024)'!$B$10:$L$96,'Ke hoach giảng dạy CNTT'!M$6,0) -> [71ITBS10203]Cơ sở lập trình | Q34: =Q33 -> 4 | R34: =IFERROR(VLOOKUP(D34,$D$9:D33,1,0),"")
A35: HK252 5 | B35: 2 | D35: 71POLS10032 | E35: =VLOOKUP($D35,'Khung_CTĐT_CNTT_K30 (2024)'!$B$10:$L$96,'Ke hoach giảng dạy CNTT'!E$6,0) -> Chủ nghĩa xã hội khoa học | F35: =VLOOKUP($D35,'Khung_CTĐT_CNTT_K30 (2024)'!$B$10:$L$96,'Ke hoach giảng dạy CNTT'!F$6,0) -> 2 | G35: =VLOOKUP($D35,'Khung_CTĐT_CNTT_K30 (2024)'!$B$10:$L$96,'Ke hoach giảng dạy CNTT'!G$6,0) -> 30 | H35: =VLOOKUP($D35,'Khung_CTĐT_CNTT_K30 (2024)'!$B$10:$L$96,'Ke hoach giảng dạy CNTT'!H$6,0) -> 0 | I35: =VLOOKUP($D35,'Khung_CTĐT_CNTT_K30 (2024)'!$B$10:$L$96,'Ke hoach giảng dạy CNTT'!I$6,0) -> 0 | J35: =VLOOKUP($D35,'Khung_CTĐT_CNTT_K30 (2024)'!$B$10:$L$96,'Ke hoach giảng dạy CNTT'!J$6,0) -> 0 | K35: =VLOOKUP($D35,'Khung_CTĐT_CNTT_K30 (2024)'!$B$10:$L$96,'Ke hoach giảng dạy CNTT'!K$6,0) -> BB | L35: =VLOOKUP($D35,'Khung_CTĐT_CNTT_K30 (2024)'!$B$10:$L$96,'Ke hoach giảng dạy CNTT'!L$6,0) -> Không | M35: =VLOOKUP($D35,'Khung_CTĐT_CNTT_K30 (2024)'!$B$10:$L$96,'Ke hoach giảng dạy CNTT'!M$6,0) -> [71POLP10013]Triết học Mác-Lênin | N35: =SUM(F35:F37)+6 -> 14 | P35: =P30+N35 -> 69 | Q35: 5 | R35: =IFERROR(VLOOKUP(D35,$D$9:D34,1,0),"")
B36: 2 | C36: 2 | D36: 71ENG510053 | E36: =VLOOKUP($D36,'Khung_CTĐT_CNTT_K30 (2024)'!$B$10:$L$96,'Ke hoach giảng dạy CNTT'!E$6,0) -> Anh văn 5 (AV5) | F36: =VLOOKUP($D36,'Khung_CTĐT_CNTT_K30 (2024)'!$B$10:$L$96,'Ke hoach giảng dạy CNTT'!F$6,0) -> 3 | G36: =VLOOKUP($D36,'Khung_CTĐT_CNTT_K30 (2024)'!$B$10:$L$96,'Ke hoach giảng dạy CNTT'!G$6,0) -> 30 | H36: =VLOOKUP($D36,'Khung_CTĐT_CNTT_K30 (2024)'!$B$10:$L$96,'Ke hoach giảng dạy CNTT'!H$6,0) -> 30 | I36: =VLOOKUP($D36,'Khung_CTĐT_CNTT_K30 (2024)'!$B$10:$L$96,'Ke hoach giảng dạy CNTT'!I$6,0) -> 0 | J36: =VLOOKUP($D36,'Khung_CTĐT_CNTT_K30 (2024)'!$B$10:$L$96,'Ke hoach giảng dạy CNTT'!J$6,0) -> 0 | K36: =VLOOKUP($D36,'Khung_CTĐT_CNTT_K30 (2024)'!$B$10:$L$96,'Ke hoach giảng dạy CNTT'!K$6,0) -> BB | L36: =VLOOKUP($D36,'Khung_CTĐT_CNTT_K30 (2024)'!$B$10:$L$96,'Ke hoach giảng dạy CNTT'!L$6,0) -> [71ENG410043]Anh văn 4 (AV4) | M36: =VLOOKUP($D36,'Khung_CTĐT_CNTT_K30 (2024)'!$B$10:$L$96,'Ke hoach giảng dạy CNTT'!M$6,0) -> Không | Q36: =Q35 -> 5 | R36: =IFERROR(VLOOKUP(D36,$D$9:D35,1,0),"")
B37: 2 | C37: 2 | D37: 71ITDS30103 | E37: =VLOOKUP($D37,'Khung_CTĐT_CNTT_K30 (2024)'!$B$10:$L$96,'Ke hoach giảng dạy CNTT'!E$6,0) -> Các nền tảng phát triển phần mềm | F37: =VLOOKUP($D37,'Khung_CTĐT_CNTT_K30 (2024)'!$B$10:$L$96,'Ke hoach giảng dạy CNTT'!F$6,0) -> 3 | G37: =VLOOKUP($D37,'Khung_CTĐT_CNTT_K30 (2024)'!$B$10:$L$96,'Ke hoach giảng dạy CNTT'!G$6,0) -> 30 | H37: =VLOOKUP($D37,'Khung_CTĐT_CNTT_K30 (2024)'!$B$10:$L$96,'Ke hoach giảng dạy CNTT'!H$6,0) -> 30 | I37: =VLOOKUP($D37,'Khung_CTĐT_CNTT_K30 (2024)'!$B$10:$L$96,'Ke hoach giảng dạy CNTT'!I$6,0) -> 0 | J37: =VLOOKUP($D37,'Khung_CTĐT_CNTT_K30 (2024)'!$B$10:$L$96,'Ke hoach giảng dạy CNTT'!J$6,0) -> 0 | K37: =VLOOKUP($D37,'Khung_CTĐT_CNTT_K30 (2024)'!$B$10:$L$96,'Ke hoach giảng dạy CNTT'!K$6,0) -> BB | L37: =VLOOKUP($D37,'Khung_CTĐT_CNTT_K30 (2024)'!$B$10:$L$96,'Ke hoach giảng dạy CNTT'!L$6,0) -> Không | M37: =VLOOKUP($D37,'Khung_CTĐT_CNTT_K30 (2024)'!$B$10:$L$96,'Ke hoach giảng dạy CNTT'!M$6,0) -> [71ITBS10103]Nhập môn công nghệ thông tin | Q37: =Q36 -> 5 | R37: =IFERROR(VLOOKUP(D37,$D$9:D36,1,0),"")
C38: Chọn 2 trong 6 HP tự chọn Cơ sở ngành | Q38: =Q37 -> 5 | R38: =IFERROR(VLOOKUP(D38,$D$9:D37,1,0),"")
B39: 2 | C39: 2 | D39: 71ISBC30103 | E39: =VLOOKUP($D39,'Khung_CTĐT_CNTT_K30 (2024)'!$B$10:$L$96,'Ke hoach giảng dạy CNTT'!E$6,0) -> Nhập môn Hệ thống thông tin | F39: =VLOOKUP($D39,'Khung_CTĐT_CNTT_K30 (2024)'!$B$10:$L$96,'Ke hoach giảng dạy CNTT'!F$6,0) -> 3 | G39: =VLOOKUP($D39,'Khung_CTĐT_CNTT_K30 (2024)'!$B$10:$L$96,'Ke hoach giảng dạy CNTT'!G$6,0) -> 30 | H39: =VLOOKUP($D39,'Khung_CTĐT_CNTT_K30 (2024)'!$B$10:$L$96,'Ke hoach giảng dạy CNTT'!H$6,0) -> 30 | I39: =VLOOKUP($D39,'Khung_CTĐT_CNTT_K30 (2024)'!$B$10:$L$96,'Ke hoach giảng dạy CNTT'!I$6,0) -> 0 | J39: =VLOOKUP($D39,'Khung_CTĐT_CNTT_K30 (2024)'!$B$10:$L$96,'Ke hoach giảng dạy CNTT'!J$6,0) -> 0 | K39: =VLOOKUP($D39,'Khung_CTĐT_CNTT_K30 (2024)'!$B$10:$L$96,'Ke hoach giảng dạy CNTT'!K$6,0) -> TC209 | L39: =VLOOKUP($D39,'Khung_CTĐT_CNTT_K30 (2024)'!$B$10:$L$96,'Ke hoach giảng dạy CNTT'!L$6,0) -> Không | M39: =VLOOKUP($D39,'Khung_CTĐT_CNTT_K30 (2024)'!$B$10:$L$96,'Ke hoach giảng dạy CNTT'!M$6,0) -> [71ITBS10103]Nhập môn công nghệ thông tin | Q39: =Q38 -> 5 | R39: =IFERROR(VLOOKUP(D39,$D$9:D38,1,0),"")
B40: 2 | C40: 2 | D40: 71ITNW30303 | E40: =VLOOKUP($D40,'Khung_CTĐT_CNTT_K30 (2024)'!$B$10:$L$96,'Ke hoach giảng dạy CNTT'!E$6,0) -> An ninh Mạng máy tính | F40: =VLOOKUP($D40,'Khung_CTĐT_CNTT_K30 (2024)'!$B$10:$L$96,'Ke hoach giảng dạy CNTT'!F$6,0) -> 3 | G40: =VLOOKUP($D40,'Khung_CTĐT_CNTT_K30 (2024)'!$B$10:$L$96,'Ke hoach giảng dạy CNTT'!G$6,0) -> 30 | H40: =VLOOKUP($D40,'Khung_CTĐT_CNTT_K30 (2024)'!$B$10:$L$96,'Ke hoach giảng dạy CNTT'!H$6,0) -> 30 | I40: =VLOOKUP($D40,'Khung_CTĐT_CNTT_K30 (2024)'!$B$10:$L$96,'Ke hoach giảng dạy CNTT'!I$6,0) -> 0 | J40: =VLOOKUP($D40,'Khung_CTĐT_CNTT_K30 (2024)'!$B$10:$L$96,'Ke hoach giảng dạy CNTT'!J$6,0) -> 0 | K40: =VLOOKUP($D40,'Khung_CTĐT_CNTT_K30 (2024)'!$B$10:$L$96,'Ke hoach giảng dạy CNTT'!K$6,0) -> TC209 | L40: =VLOOKUP($D40,'Khung_CTĐT_CNTT_K30 (2024)'!$B$10:$L$96,'Ke hoach giảng dạy CNTT'!L$6,0) -> Không | M40: =VLOOKUP($D40,'Khung_CTĐT_CNTT_K30 (2024)'!$B$10:$L$96,'Ke hoach giảng dạy CNTT'!M$6,0) -> Không | Q40: =Q39 -> 5 | R40: =IFERROR(VLOOKUP(D40,$D$9:D39,1,0),"")
B41: 2 | C41: 2 | D41: 71ITDS40203 | E41: =VLOOKUP($D41,'Khung_CTĐT_CNTT_K30 (2024)'!$B$10:$L$96,'Ke hoach giảng dạy CNTT'!E$6,0) -> Xác xuất thống kê ứng dụng | F41: =VLOOKUP($D41,'Khung_CTĐT_CNTT_K30 (2024)'!$B$10:$L$96,'Ke hoach giảng dạy CNTT'!F$6,0) -> 3 | G41: =VLOOKUP($D41,'Khung_CTĐT_CNTT_K30 (2024)'!$B$10:$L$96,'Ke hoach giảng dạy CNTT'!G$6,0) -> 30 | H41: =VLOOKUP($D41,'Khung_CTĐT_CNTT_K30 (2024)'!$B$10:$L$96,'Ke hoach giảng dạy CNTT'!H$6,0) -> 30 | I41: =VLOOKUP($D41,'Khung_CTĐT_CNTT_K30 (2024)'!$B$10:$L$96,'Ke hoach giảng dạy CNTT'!I$6,0) -> 0 | J41: =VLOOKUP($D41,'Khung_CTĐT_CNTT_K30 (2024)'!$B$10:$L$96,'Ke hoach giảng dạy CNTT'!J$6,0) -> 0 | K41: =VLOOKUP($D41,'Khung_CTĐT_CNTT_K30 (2024)'!$B$10:$L$96,'Ke hoach giảng dạy CNTT'!K$6,0) -> TC209 | L41: =VLOOKUP($D41,'Khung_CTĐT_CNTT_K30 (2024)'!$B$10:$L$96,'Ke hoach giảng dạy CNTT'!L$6,0) -> Không | M41: =VLOOKUP($D41,'Khung_CTĐT_CNTT_K30 (2024)'!$B$10:$L$96,'Ke hoach giảng dạy CNTT'!M$6,0) -> [71ITMA10403]Toán rời rạc | Q41: =Q40 -> 5 | R41: =IFERROR(VLOOKUP(D41,$D$9:D40,1,0),"")
B42: 2 | C42: 2 | D42: 71ITIS30303 | E42: =VLOOKUP($D42,'Khung_CTĐT_CNTT_K30 (2024)'!$B$10:$L$96,'Ke hoach giảng dạy CNTT'!E$6,0) -> Quản lý Dự án Công nghệ Thông tin | F42: =VLOOKUP($D42,'Khung_CTĐT_CNTT_K30 (2024)'!$B$10:$L$96,'Ke hoach giảng dạy CNTT'!F$6,0) -> 3 | G42: =VLOOKUP($D42,'Khung_CTĐT_CNTT_K30 (2024)'!$B$10:$L$96,'Ke hoach giảng dạy CNTT'!G$6,0) -> 30 | H42: =VLOOKUP($D42,'Khung_CTĐT_CNTT_K30 (2024)'!$B$10:$L$96,'Ke hoach giảng dạy CNTT'!H$6,0) -> 30 | I42: =VLOOKUP($D42,'Khung_CTĐT_CNTT_K30 (2024)'!$B$10:$L$96,'Ke hoach giảng dạy CNTT'!I$6,0) -> 0 | J42: =VLOOKUP($D42,'Khung_CTĐT_CNTT_K30 (2024)'!$B$10:$L$96,'Ke hoach giảng dạy CNTT'!J$6,0) -> 0 | K42: =VLOOKUP($D42,'Khung_CTĐT_CNTT_K30 (2024)'!$B$10:$L$96,'Ke hoach giảng dạy CNTT'!K$6,0) -> TC209 | L42: =VLOOKUP($D42,'Khung_CTĐT_CNTT_K30 (2024)'!$B$10:$L$96,'Ke hoach giảng dạy CNTT'!L$6,0) -> Không | M42: =VLOOKUP($D42,'Khung_CTĐT_CNTT_K30 (2024)'!$B$10:$L$96,'Ke hoach giảng dạy CNTT'!M$6,0) -> [71ITBS10103]Nhập môn công nghệ thông tin | Q42: =Q40 -> 5 | R42: =IFERROR(VLOOKUP(D42,$D$9:D40,1,0),"")
...

Sheet Khung_CTĐT_CNTT_K30 (2024)
A2: TRƯỜNG ĐẠI HỌC VĂN LANG
A3: KHOA CÔNG NGHỆ THÔNG TIN
A5: KHUNG CHƯƠNG TRÌNH ĐÀO TẠO NGÀNH CÔNG NGHỆ THÔNG TIN KHÓA 30
A7: Tổng tín chỉ của CTĐT: 126 tín chỉ
B8: 1 | C8: 2 | D8: 3 | E8: 4 | F8: 5 | G8: 6 | H8: 7 | I8: 8 | J8: 9 | K8: 10 | L8: 11 | M8: 12 | N8: 13 | O8: 14 | P8: 15 | Q8: 16
A9: TT | B9: Mã học phần | C9: Tên học phần tiếng Việt | D9: Tên học phần tiếng Anh | E9: Số tín chỉ | F9: LT | G9: TH | H9: ĐA | I9: TT | J9: BB/TC | K9: Điều kiện tiên quyết | L9: Điều kiện học trước | M9: Khối kiến thức | N9: Tên chuyên ngành/chuyên sâu | O9: Ghi chú | P9: Mã BM | Q9: BM phụ trách | R9: Học kỳ | S9: Năm thứ
A10: =COUNTA($B$10:B10) -> 1 | B10: 71LAWG10012 | C10: Pháp luật đại cương | D10: General Law | E10: 2 | F10: 30 | G10: 0 | H10: 0 | J10: BB | K10: Không | L10: Không | M10: Đại cương | P10: 200110201 | Q10: Bộ Môn Luật Hành chính - Nhà nước | R10: 1 | S10: 3
A11: =COUNTA($B$10:B11) -> 2 | B11: 71ENVH10012 | C11: Môi trường và con người | E11: 2 | F11: 30 | G11: 0 | H11: 0 | J11: BB | K11: Không | L11: Không | M11: Đại cương | P11: 200111302 | Q11: Bộ môn Công nghệ kỹ thuật môi trường | R11: 1 | S11: 3
A12: =COUNTA($B$10:B12) -> 3 | B12: 71ITMA10104 | C12: Toán cao cấp và ứng dụng | D12: Advanced Calculus | E12: 4 | F12: 45 | G12: 30 | H12: 0 | J12: BB | K12: Không | L12: Không | M12: Đại cương | P12: 200110701 | Q12: Bộ môn Khoa học dữ liệu | R12: 2 | S12: 1
A13: =COUNTA($B$10:B13) -> 4 | B13: 71MATL10053 | C13: Đại số tuyến tính và ứng dụng | D13: Linear Algebra | E13: 3 | F13: 30 | G13: 30 | H13: 0 | J13: BB | K13: Không | L13: Không | M13: Đại cương | P13: 200110701 | Q13: Bộ môn Khoa học dữ liệu | R13: 3 | S13: 1
A14: =COUNTA($B$10:B14) -> 5 | B14: 71SSK110023 | C14: Kỹ năng công dân toàn cầu | E14: 3 | F14: 45 | G14: 0 | H14: 0 | J14: BB | K14: Không | L14: Không | M14: Đại cương | P14: 2001206 | Q14: Trung tâm Phát triển năng lực sinh viên | R14: 1 | S14: 1
A15: =COUNTA($B$10:B15) -> 6 | B15: 71POLP10013 | C15: Triết học Mác-Lênin | D15: Philosophy of Marxism and Leninism | E15: 3 | F15: 45 | G15: 0 | H15: 0 | J15: BB | K15: Không | L15: Không | M15: Lý luận chính trị | P15: 200111206 | Q15: Bộ môn Triết học và Chủ nghĩa XHKH | R15: 2 | S15: 1
A16: =COUNTA($B$10:B16) -> 7 | B16: 71POLE10022 | C16: Kinh tế chính trị Mác-Lênin | D16: Marxist – Leninist Political Economy | E16: 2 | F16: 30 | G16: 0 | H16: 0 | J16: BB | K16: Không | L16: [71POLP10013]Triết học Mác-Lênin | M16: Lý luận chính trị | P16: 200111208 | Q16: Bộ môn Kinh tế chính trị Mác - Lênin | R16: 3 | S16: 1
A17: =COUNTA($B$10:B17) -> 8 | B17: 71POLS10032 | C17: Chủ nghĩa xã hội khoa học | D17: Scientific Socialism | E17: 2 | F17: 30 | G17: 0 | H17: 0 | J17: BB | K17: Không | L17: [71POLP10013]Triết học Mác-Lênin | M17: Lý luận chính trị | P17: 200111206 | Q17: Bộ môn Triết học và Chủ nghĩa XHKH | R17: 1 | S17: 2
A18: =COUNTA($B$10:B18) -> 9 | B18: 71POLH10042 | C18: Tư tưởng Hồ Chí Minh | D18: Ho Chi Minh's Thought | E18: 2 | F18: 30 | G18: 0 | H18: 0 | J18: BB | K18: Không | L18: [71POLE10022]Kinh tế chính trị Mác-Lênin, [71POLS10032]Chủ nghĩa xã hội khoa học | M18: Lý luận chính trị | P18: 200111207 | Q18: Bộ môn Lịch sử Đảng CSVN và Tư tưởng HCM | R18: 2 | S18: 2
A19: =COUNTA($B$10:B19) -> 10 | B19: 71POLC10052 | C19: Lịch sử Đảng Cộng sản Việt Nam | D19: History of Vietnamese Communist Party | E19: 2 | F19: 30 | G19: 0 | H19: 0 | J19: BB | K19: Không | L19: [71POLE10022]Kinh tế chính trị Mác-Lênin, [71POLS10032]Chủ nghĩa xã hội khoa học | M19: Lý luận chính trị | P19: 200111207 | Q19: Bộ môn Lịch sử Đảng CSVN và Tư tưởng HCM | R19: 3 | S19: 2
A20: =COUNTA($B$10:B20) -> 11 | B20: 71ENG110013 | C20: Anh văn 1 (AV1) | D20: English 1 | E20: 3 | F20: 30 | G20: 30 | H20: 0 | J20: BB | K20: [71ENG010012]Anh văn dự bị (AV0) | L20: Không | M20: Ngoại ngữ | P20: 200112601 | Q20: Bộ môn Anh văn tổng quát | R20: 1 | S20: 1
A21: =COUNTA($B$10:B21) -> 12 | B21: 71ENG210023 | C21: Anh văn 2 (AV2) | D21: English 2 | E21: 3 | F21: 30 | G21: 30 | H21: 0 | J21: BB | K21: [71ENG110013]Anh văn 1 (AV1) | L21: Không | M21: Ngoại ngữ | P21: 200112601 | Q21: Bộ môn Anh văn tổng quát | R21: 2 | S21: 1
A22: =COUNTA($B$10:B22) -> 13 | B22: 71ENG310033 | C22: Anh văn 3 (AV3) | D22: English 3 | E22: 3 | F22: 30 | G22: 30 | H22: 0 | J22: BB | K22: [71ENG210023]Anh văn 2 (AV2) | L22: Không | M22: Ngoại ngữ | P22: 200112601 | Q22: Bộ môn Anh văn tổng quát | R22: 3 | S22: 1
A23: =COUNTA($B$10:B23) -> 14 | B23: 71ENG410043 | C23: Anh văn 4 (AV4) | D23: English 4 | E23: 3 | F23: 30 | G23: 30 | H23: 0 | J23: BB | K23: [71ENG310033]Anh văn 3 (AV3) | L23: Không | M23: Ngoại ngữ | P23: 200112601 | Q23: Bộ môn Anh văn tổng quát | R23: 1 | S23: 2
A24: =COUNTA($B$10:B24) -> 15 | B24: 71ENG510053 | C24: Anh văn 5 (AV5) | D24: English 5 | E24: 3 | F24: 30 | G24: 30 | H24: 0 | J24: BB | K24: [71ENG410043]Anh văn 4 (AV4) | L24: Không | M24: Ngoại ngữ | P24: 200112601 | Q24: Bộ môn Anh văn tổng quát | R24: 2 | S24: 2
A25: =COUNTA($B$10:B25) -> 16 | B25: 71ENG610063 | C25: Anh văn 6 (AV6) | D25: English 6 | E25: 3 | F25: 45 | G25: 0 | H25: 0 | J25: BB | K25: [71ENG510053]Anh văn 5 (AV5) | L25: Không | M25: Ngoại ngữ | P25: 200112601 | Q25: Bộ môn Anh văn tổng quát | R25: 3 | S25: 2
A26: =COUNTA($B$10:B26) -> 17 | B26: 71ENG710073 | C26: Anh văn 7 (AV7) | D26: English 7 | E26: 3 | F26: 45 | G26: 0 | H26: 0 | J26: BB | K26: [71ENG610063]Anh văn 6 (AV6) | L26: Không | M26: Ngoại ngữ | P26: 200112601 | Q26: Bộ môn Anh văn tổng quát | R26: 1 | S26: 3
A27: =COUNTA($B$10:B27) -> 18 | B27: 71PEKC10062 | C27: Cờ vua | E27: 2 | F27: 45 | G27: 60 | H27: 0 | J27: TC002 (2TC) | K27: Không | L27: Không | M27: Giáo dục thể chất và giáo dục quốc phòng | P27: 200113501 | Q27: Bộ môn Giáo dục thể chất | R27: 2 | S27: 1
A28: =COUNTA($B$10:B28) -> 19 | B28: 71PESW10042 | C28: Bơi lội | E28: 2 | F28: 45 | G28: 60 | H28: 0 | J28: TC002 (2TC) | K28: Không | L28: Không | M28: Giáo dục thể chất và giáo dục quốc phòng | P28: 200113501 | Q28: Bộ môn Giáo dục thể chất | R28: 2 | S28: 1
A29: =COUNTA($B$10:B29) -> 20 | B29: 71PEYO10142 | C29: Hatha yoga | E29: 2 | F29: 45 | G29: 8 | H29: 0 | J29: TC002 (2TC) | K29: Không | L29: Không | M29: Giáo dục thể chất và giáo dục quốc phòng | P29: 200113501 | Q29: Bộ môn Giáo dục thể chất | R29: 2 | S29: 1
A30: =COUNTA($B$10:B30) -> 21 | B30: 71PEKC10172 | C30: Cờ vua nâng cao | E30: 2 | F30: 45 | G30: 8 | H30: 0 | J30: TC102 (2TC) | K30: Không | L30: [71PEKC10062]Cờ vua | M30: Giáo dục thể chất và giáo dục quốc phòng | P30: 200113501 | Q30: Bộ môn Giáo dục thể chất | R30: 3 | S30: 1
A31: =COUNTA($B$10:B31) -> 22 | B31: 71PEBA10052 | C31: Cầu lông | E31: 2 | F31: 45 | G31: 16 | H31: 0 | J31: TC102 (2TC) | K31: Không | L31: Không | M31: Giáo dục thể chất và giáo dục quốc phòng | P31: 200113501 | Q31: Bộ môn Giáo dục thể chất | R31: 3 | S31: 1
A32: =COUNTA($B$10:B32) -> 23 | B32: 71PEBB10032 | C32: Bóng rổ | E32: 2 | F32: 45 | J32: TC102 (2TC) | K32: Không | L32: Không | M32: Giáo dục thể chất và giáo dục quốc phòng | P32: 200113501 | Q32: Bộ môn Giáo dục thể chất | R32: 3 | S32: 1
A33: =COUNTA($B$10:B33) -> 24 | B33: 71PEDA10102 | C33: Khiêu vũ | E33: 2 | F33: 45 | J33: TC102 (2TC) | K33: Không | L33: Không | M33: Giáo dục thể chất và giáo dục quốc phòng | P33: 200113501 | Q33: Bộ môn Giáo dục thể chất | R33: 3 | S33: 1
A34: =COUNTA($B$10:B34) -> 25 | B34: 71PEFI10072 | C34: Fitness | E34: 2 | F34: 45 | J34: TC102 (2TC) | K34: Không | L34: Không | M34: Giáo dục thể chất và giáo dục quốc phòng | P34: 200113501 | Q34: Bộ môn Giáo dục thể chất | R34: 3 | S34: 1
A35: =COUNTA($B$10:B35) -> 26 | B35: 71PEFU10082 | C35: Futsal | E35: 2 | F35: 45 | J35: TC102 (2TC) | K35: Không | L35: Không | M35: Giáo dục thể chất và giáo dục quốc phòng | P35: 200113501 | Q35: Bộ môn Giáo dục thể chất | R35: 3 | S35: 1
A36: =COUNTA($B$10:B36) -> 27 | B36: 71PEGO10092 | C36: Golf | E36: 2 | F36: 45 | J36: TC102 (2TC) | K36: Không | L36: Không | M36: Giáo dục thể chất và giáo dục quốc phòng | P36: 200113501 | Q36: Bộ môn Giáo dục thể chất | R36: 3 | S36: 1
A37: =COUNTA($B$10:B37) -> 28 | B37: 71PEMA10132 | C37: Võ thuật | E37: 2 | F37: 45 | J37: TC102 (2TC) | K37: Không | L37: Không | M37: Giáo dục thể chất và giáo dục quốc phòng | P37: 200113501 | Q37: Bộ môn Giáo dục thể chất | R37: 3 | S37: 1
A38: =COUNTA($B$10:B38) -> 29 | B38: 71PEMT10152 | C38: Marathon | E38: 2 | F38: 45 | J38: TC102 (2TC) | K38: Không | L38: Không | M38: Giáo dục thể chất và giáo dục quốc phòng | P38: 200113501 | Q38: Bộ môn Giáo dục thể chất | R38: 3 | S38: 1
A39: =COUNTA($B$10:B39) -> 30 | B39: 71PESC10112 | C39: Leo núi thể thao | E39: 2 | F39: 45 | J39: TC102 (2TC) | K39: Không | L39: Không | M39: Giáo dục thể chất và giáo dục quốc phòng | P39: 200113501 | Q39: Bộ môn Giáo dục thể chất | R39: 3 | S39: 1
A40: =COUNTA($B$10:B40) -> 31 | B40: 71PESS10162 | C40: Bắn súng thể thao | E40: 2 | F40: 45 | J40: TC102 (2TC) | K40: Không | L40: Không | M40: Giáo dục thể chất và giáo dục quốc phòng | P40: 200113501 | Q40: Bộ môn Giáo dục thể chất | R40: 3 | S40: 1
A41: =COUNTA($B$10:B41) -> 32 | B41: 71PETE10122 | C41: Tennis | E41: 2 | F41: 45 | J41: TC102 (2TC) | K41: Không | L41: Không | M41: Giáo dục thể chất và giáo dục quốc phòng | P41: 200113501 | Q41: Bộ môn Giáo dục thể chất | R41: 3 | S41: 1
A42: =COUNTA($B$10:B42) -> 33 | B42: 71PETT10012 | C42: Bóng bàn | E42: 2 | F42: 45 | J42: TC102 (2TC) | K42: Không | L42: Không | M42: Giáo dục thể chất và giáo dục quốc phòng | P42: 200113501 | Q42: Bộ môn Giáo dục thể chất | R42: 3 | S42: 1
A43: =COUNTA($B$10:B43) -> 34 | B43: 71PEVB10022 | C43: Bóng chuyền | E43: 2 | F43: 45 | J43: TC102 (2TC) | K43: Không | L43: Không | M43: Giáo dục thể chất và giáo dục quốc phòng | P43: 200113501 | Q43: Bộ môn Giáo dục thể chất | R43: 3 | S43: 1
...

Sheet CTĐT_CNTT_K30 (2025 Mẫu Khoa)
A2: TRƯỜNG ĐẠI HỌC VĂN LANG
A3: KHOA CÔNG NGHỆ THÔNG TIN
A5: KHUNG CHƯƠNG TRÌNH ĐÀO TẠO NGÀNH CÔNG NGHỆ THÔNG TIN KHÓA 30
A7: Tổng tín chỉ của CTĐT: 126 tín chỉ
E8: =E10+E53 -> 126
A9: TT | B9: Mã học phần | C9: Tên học phần tiếng Việt | D9: Tên học phần tiếng Anh | E9: Số tín chỉ | F9: LT | G9: TH | H9: ĐA | I9: TT | J9: BB/TC | K9: Điều kiện tiên quyết | L9: Điều kiện học trước | M9: Khối kiến thức | N9: Tên chuyên ngành/chuyên sâu | O9: Ghi chú | P9: Mã BM | Q9: BM phụ trách | R9: Học kỳ | S9: Năm thứ
A10: Khối kiến thức: I. Kiến thức giáo dục đại cương | E10: =E11+E17+E23 -> 46 | F10: TC
A11: Khối kiến thức: I. Kiến thức giáo dục đại cương | E11: =SUM(E12:E16) -> 14 | F11: TC
A12: =COUNTA($B$12:B12) -> 1 | B12: 71LAWG10012 | C12: Pháp luật đại cương | D12: General Law | E12: 2 | F12: 30 | G12: 0 | H12: 0 | J12: BB | K12: Không | L12: Không | M12: Đại cương | P12: 200110201 | Q12: Bộ Môn Luật Hành chính - Nhà nước | R12: 1 | S12: 3 | W12: =_xlfn.XLOOKUP(B12,[2]Sheet!$C$10:$C$107,[2]Sheet!$K$10:$K$107) -> 0 | X12: =IF(W12=0,"Không",W12) -> Không
A13: =COUNTA($B$12:B13) -> 2 | B13: 71ENVH10012 | C13: Môi trường và con người | E13: 2 | F13: 30 | G13: 0 | H13: 0 | J13: BB | K13: Không | L13: Không | M13: Đại cương | P13: 200111302 | Q13: Bộ môn Công nghệ kỹ thuật môi trường | R13: 1 | S13: 3 | W13: =_xlfn.XLOOKUP(B13,[2]Sheet!$C$10:$C$107,[2]Sheet!$K$10:$K$107) -> 0 | X13: =IF(W13=0,"Không",W13) -> Không
A14: =COUNTA($B$12:B14) -> 3 | B14: 71ITMA10104 | C14: Toán cao cấp và ứng dụng | D14: Advanced Calculus | E14: 4 | F14: 45 | G14: 30 | H14: 0 | J14: BB | K14: Không | L14: Không | M14: Đại cương | P14: 200110701 | Q14: Bộ môn Khoa học dữ liệu | R14: 2 | S14: 1 | W14: =_xlfn.XLOOKUP(B14,[2]Sheet!$C$10:$C$107,[2]Sheet!$K$10:$K$107) -> 0 | X14: =IF(W14=0,"Không",W14) -> Không
A15: =COUNTA($B$12:B15) -> 4 | B15: 71MATL10053 | C15: Đại số tuyến tính và ứng dụng | D15: Linear Algebra | E15: 3 | F15: 30 | G15: 30 | H15: 0 | J15: BB | K15: Không | L15: Không | M15: Đại cương | P15: 200110701 | Q15: Bộ môn Khoa học dữ liệu | R15: 3 | S15: 1 | W15: =_xlfn.XLOOKUP(B15,[2]Sheet!$C$10:$C$107,[2]Sheet!$K$10:$K$107) -> 0 | X15: =IF(W15=0,"Không",W15) -> Không
A16: =COUNTA($B$12:B16) -> 5 | B16: 71SSK110023 | C16: Kỹ năng công dân toàn cầu | E16: 3 | F16: 45 | G16: 0 | H16: 0 | J16: BB | K16: Không | L16: Không | M16: Đại cương | P16: 2001206 | Q16: Trung tâm Phát triển năng lực sinh viên | R16: 1 | S16: 1 | W16: =_xlfn.XLOOKUP(B16,[2]Sheet!$C$10:$C$107,[2]Sheet!$K$10:$K$107) -> 0 | X16: =IF(W16=0,"Không",W16) -> Không
A17: Khối kiến thức: I.1. Lý luận chính trị | E17: =SUM(E18:E22) -> 11 | F17: TC | W17: =_xlfn.XLOOKUP(B17,[2]Sheet!$C$10:$C$107,[2]Sheet!$K$10:$K$107) -> 0 | X17: =IF(W17=0,"Không",W17) -> Không
A18: 1 | B18: 71POLP10013 | C18: Triết học Mác-Lênin | D18: Philosophy of Marxism and Leninism | E18: 3 | F18: 45 | G18: 0 | H18: 0 | J18: BB | K18: Không | L18: Không | M18: Lý luận chính trị | P18: 200111206 | Q18: Bộ môn Triết học và Chủ nghĩa XHKH | R18: 2 | S18: 1 | W18: =_xlfn.XLOOKUP(B18,[2]Sheet!$C$10:$C$107,[2]Sheet!$K$10:$K$107) -> 0 | X18: =IF(W18=0,"Không",W18) -> Không
A19: 2 | B19: 71POLE10022 | C19: Kinh tế chính trị Mác-Lênin | D19: Marxist – Leninist Political Economy | E19: 2 | F19: 30 | G19: 0 | H19: 0 | J19: BB | K19: Không | L19: [71POLP10013]Triết học Mác-Lênin | M19: Lý luận chính trị | P19: 200111208 | Q19: Bộ môn Kinh tế chính trị Mác - Lênin | R19: 3 | S19: 1 | W19: =_xlfn.XLOOKUP(B19,[2]Sheet!$C$10:$C$107,[2]Sheet!$K$10:$K$107) -> [71POLP10013]Triết học Mác-Lênin | X19: =IF(W19=0,"Không",W19) -> [71POLP10013]Triết học Mác-Lênin
A20: 3 | B20: 71POLS10032 | C20: Chủ nghĩa xã hội khoa học | D20: Scientific Socialism | E20: 2 | F20: 30 | G20: 0 | H20: 0 | J20: BB | K20: Không | L20: [71POLP10013]Triết học Mác-Lênin | M20: Lý luận chính trị | P20: 200111206 | Q20: Bộ môn Triết học và Chủ nghĩa XHKH | R20: 1 | S20: 2 | W20: =_xlfn.XLOOKUP(B20,[2]Sheet!$C$10:$C$107,[2]Sheet!$K$10:$K$107) -> [71POLP10013]Triết học Mác-Lênin | X20: =IF(W20=0,"Không",W20) -> [71POLP10013]Triết học Mác-Lênin
A21: 4 | B21: 71POLH10042 | C21: Tư tưởng Hồ Chí Minh | D21: Ho Chi Minh's Thought | E21: 2 | F21: 30 | G21: 0 | H21: 0 | J21: BB | K21: Không | L21: [71POLE10022]Kinh tế chính trị Mác-Lênin, [71POLS10032]Chủ nghĩa xã hội khoa học | M21: Lý luận chính trị | P21: 200111207 | Q21: Bộ môn Lịch sử Đảng CSVN và Tư tưởng HCM | R21: 2 | S21: 2 | W21: =_xlfn.XLOOKUP(B21,[2]Sheet!$C$10:$C$107,[2]Sheet!$K$10:$K$107) -> [71POLE10022]Kinh tế chính trị Mác-Lênin, [71POLS10032]Chủ nghĩa xã hội khoa học | X21: =IF(W21=0,"Không",W21) -> [71POLE10022]Kinh tế chính trị Mác-Lênin, [71POLS10032]Chủ nghĩa xã hội khoa học
A22: 5 | B22: 71POLC10052 | C22: Lịch sử Đảng Cộng sản Việt Nam | D22: History of Vietnamese Communist Party | E22: 2 | F22: 30 | G22: 0 | H22: 0 | J22: BB | K22: Không | L22: [71POLE10022]Kinh tế chính trị Mác-Lênin, [71POLS10032]Chủ nghĩa xã hội khoa học | M22: Lý luận chính trị | P22: 200111207 | Q22: Bộ môn Lịch sử Đảng CSVN và Tư tưởng HCM | R22: 3 | S22: 2 | W22: =_xlfn.XLOOKUP(B22,[2]Sheet!$C$10:$C$107,[2]Sheet!$K$10:$K$107) -> [71POLE10022]Kinh tế chính trị Mác-Lênin, [71POLS10032]Chủ nghĩa xã hội khoa học | X22: =IF(W22=0,"Không",W22) -> [71POLE10022]Kinh tế chính trị Mác-Lênin, [71POLS10032]Chủ nghĩa xã hội khoa học
A23: Khối kiến thức: I.2. Ngoại ngữ | E23: =SUM(E24:E30) -> 21 | F23: TC | W23: =_xlfn.XLOOKUP(B23,[2]Sheet!$C$10:$C$107,[2]Sheet!$K$10:$K$107) -> 0 | X23: =IF(W23=0,"Không",W23) -> Không
A24: 1 | B24: 71ENG110013 | C24: Anh văn 1 (AV1) | D24: English 1 | E24: 3 | F24: 30 | G24: 30 | H24: 0 | J24: BB | K24: [71ENG010012]Anh văn dự bị (AV0) | L24: Không | M24: Ngoại ngữ | P24: 200112601 | Q24: Bộ môn Anh văn tổng quát | R24: 1 | S24: 1 | W24: =_xlfn.XLOOKUP(B24,[2]Sheet!$C$10:$C$107,[2]Sheet!$K$10:$K$107) -> 0 | X24: =IF(W24=0,"Không",W24) -> Không
A25: 2 | B25: 71ENG210023 | C25: Anh văn 2 (AV2) | D25: English 2 | E25: 3 | F25: 30 | G25: 30 | H25: 0 | J25: BB | K25: [71ENG110013]Anh văn 1 (AV1) | L25: Không | M25: Ngoại ngữ | P25: 200112601 | Q25: Bộ môn Anh văn tổng quát | R25: 2 | S25: 1 | W25: =_xlfn.XLOOKUP(B25,[2]Sheet!$C$10:$C$107,[2]Sheet!$K$10:$K$107) -> 0 | X25: =IF(W25=0,"Không",W25) -> Không
A26: 3 | B26: 71ENG310033 | C26: Anh văn 3 (AV3) | D26: English 3 | E26: 3 | F26: 30 | G26: 30 | H26: 0 | J26: BB | K26: [71ENG210023]Anh văn 2 (AV2) | L26: Không | M26: Ngoại ngữ | P26: 200112601 | Q26: Bộ môn Anh văn tổng quát | R26: 3 | S26: 1 | W26: =_xlfn.XLOOKUP(B26,[2]Sheet!$C$10:$C$107,[2]Sheet!$K$10:$K$107) -> 0 | X26: =IF(W26=0,"Không",W26) -> Không
A27: 4 | B27: 71ENG410043 | C27: Anh văn 4 (AV4) | D27: English 4 | E27: 3 | F27: 30 | G27: 30 | H27: 0 | J27: BB | K27: [71ENG310033]Anh văn 3 (AV3) | L27: Không | M27: Ngoại ngữ | P27: 200112601 | Q27: Bộ môn Anh văn tổng quát | R27: 1 | S27: 2 | W27: =_xlfn.XLOOKUP(B27,[2]Sheet!$C$10:$C$107,[2]Sheet!$K$10:$K$107) -> 0 | X27: =IF(W27=0,"Không",W27) -> Không
A28: 5 | B28: 71ENG510053 | C28: Anh văn 5 (AV5) | D28: English 5 | E28: 3 | F28: 30 | G28: 30 | H28: 0 | J28: BB | K28: [71ENG410043]Anh văn 4 (AV4) | L28: Không | M28: Ngoại ngữ | P28: 200112601 | Q28: Bộ môn Anh văn tổng quát | R28: 2 | S28: 2 | W28: =_xlfn.XLOOKUP(B28,[2]Sheet!$C$10:$C$107,[2]Sheet!$K$10:$K$107) -> 0 | X28: =IF(W28=0,"Không",W28) -> Không
A29: 6 | B29: 71ENG610063 | C29: Anh văn 6 (AV6) | D29: English 6 | E29: 3 | F29: 45 | G29: 0 | H29: 0 | J29: BB | K29: [71ENG510053]Anh văn 5 (AV5) | L29: Không | M29: Ngoại ngữ | P29: 200112601 | Q29: Bộ môn Anh văn tổng quát | R29: 3 | S29: 2 | W29: =_xlfn.XLOOKUP(B29,[2]Sheet!$C$10:$C$107,[2]Sheet!$K$10:$K$107) -> 0 | X29: =IF(W29=0,"Không",W29) -> Không
A30: 7 | B30: 71ENG710073 | C30: Anh văn 7 (AV7) | D30: English 7 | E30: 3 | F30: 45 | G30: 0 | H30: 0 | J30: BB | K30: [71ENG610063]Anh văn 6 (AV6) | L30: Không | M30: Ngoại ngữ | P30: 200112601 | Q30: Bộ môn Anh văn tổng quát | R30: 1 | S30: 3 | W30: =_xlfn.XLOOKUP(B30,[2]Sheet!$C$10:$C$107,[2]Sheet!$K$10:$K$107) -> 0 | X30: =IF(W30=0,"Không",W30) -> Không
A31: Khối kiến thức: I.6. Giáo dục thể chất và giáo dục quốc phòng | W31: =_xlfn.XLOOKUP(B31,[2]Sheet!$C$10:$C$107,[2]Sheet!$K$10:$K$107) -> 0 | X31: =IF(W31=0,"Không",W31) -> Không
A32: 1 | B32: 71PEKC10062 | C32: Cờ vua | E32: 2 | F32: 45 | G32: 60 | H32: 0 | J32: TC002 (2TC) | K32: Không | L32: Không | M32: Giáo dục thể chất và giáo dục quốc phòng | P32: 200113501 | Q32: Bộ môn Giáo dục thể chất | R32: 2 | S32: 1 | W32: =_xlfn.XLOOKUP(B32,[2]Sheet!$C$10:$C$107,[2]Sheet!$K$10:$K$107) -> 0 | X32: =IF(W32=0,"Không",W32) -> Không
A33: 2 | B33: 71PESW10042 | C33: Bơi lội | E33: 2 | F33: 45 | G33: 60 | H33: 0 | J33: TC002 (2TC) | K33: Không | L33: Không | M33: Giáo dục thể chất và giáo dục quốc phòng | P33: 200113501 | Q33: Bộ môn Giáo dục thể chất | R33: 2 | S33: 1 | W33: =_xlfn.XLOOKUP(B33,[2]Sheet!$C$10:$C$107,[2]Sheet!$K$10:$K$107) -> 0 | X33: =IF(W33=0,"Không",W33) -> Không
A34: 3 | B34: 71PEYO10142 | C34: Hatha yoga | E34: 2 | F34: 45 | G34: 8 | H34: 0 | J34: TC002 (2TC) | K34: Không | L34: Không | M34: Giáo dục thể chất và giáo dục quốc phòng | P34: 200113501 | Q34: Bộ môn Giáo dục thể chất | R34: 2 | S34: 1 | W34: =_xlfn.XLOOKUP(B34,[2]Sheet!$C$10:$C$107,[2]Sheet!$K$10:$K$107) -> 0 | X34: =IF(W34=0,"Không",W34) -> Không
A35: 4 | B35: 71PEKC10172 | C35: Cờ vua nâng cao | E35: 2 | F35: 45 | G35: 8 | H35: 0 | J35: TC102 (2TC) | K35: Không | L35: [71PEKC10062]Cờ vua | M35: Giáo dục thể chất và giáo dục quốc phòng | P35: 200113501 | Q35: Bộ môn Giáo dục thể chất | R35: 3 | S35: 1 | W35: =_xlfn.XLOOKUP(B35,[2]Sheet!$C$10:$C$107,[2]Sheet!$K$10:$K$107) -> [71PEKC10062]Cờ vua | X35: =IF(W35=0,"Không",W35) -> [71PEKC10062]Cờ vua
A36: 5 | B36: 71PEBA10052 | C36: Cầu lông | E36: 2 | F36: 45 | G36: 16 | H36: 0 | J36: TC102 (2TC) | K36: Không | L36: Không | M36: Giáo dục thể chất và giáo dục quốc phòng | P36: 200113501 | Q36: Bộ môn Giáo dục thể chất | R36: 3 | S36: 1 | W36: =_xlfn.XLOOKUP(B36,[2]Sheet!$C$10:$C$107,[2]Sheet!$K$10:$K$107) -> 0 | X36: =IF(W36=0,"Không",W36) -> Không
A37: 6 | B37: 71PEBB10032 | C37: Bóng rổ | E37: 2 | F37: 45 | J37: TC102 (2TC) | K37: Không | L37: Không | M37: Giáo dục thể chất và giáo dục quốc phòng | P37: 200113501 | Q37: Bộ môn Giáo dục thể chất | R37: 3 | S37: 1 | W37: =_xlfn.XLOOKUP(B37,[2]Sheet!$C$10:$C$107,[2]Sheet!$K$10:$K$107) -> 0 | X37: =IF(W37=0,"Không",W37) -> Không
A38: 7 | B38: 71PEDA10102 | C38: Khiêu vũ | E38: 2 | F38: 45 | J38: TC102 (2TC) | K38: Không | L38: Không | M38: Giáo dục thể chất và giáo dục quốc phòng | P38: 200113501 | Q38: Bộ môn Giáo dục thể chất | R38: 3 | S38: 1 | W38: =_xlfn.XLOOKUP(B38,[2]Sheet!$C$10:$C$107,[2]Sheet!$K$10:$K$107) -> 0 | X38: =IF(W38=0,"Không",W38) -> Không
A39: 8 | B39: 71PEFI10072 | C39: Fitness | E39: 2 | F39: 45 | J39: TC102 (2TC) | K39: Không | L39: Không | M39: Giáo dục thể chất và giáo dục quốc phòng | P39: 200113501 | Q39: Bộ môn Giáo dục thể chất | R39: 3 | S39: 1 | W39: =_xlfn.XLOOKUP(B39,[2]Sheet!$C$10:$C$107,[2]Sheet!$K$10:$K$107) -> 0 | X39: =IF(W39=0,"Không",W39) -> Không
A40: 9 | B40: 71PEFU10082 | C40: Futsal | E40: 2 | F40: 45 | J40: TC102 (2TC) | K40: Không | L40: Không | M40: Giáo dục thể chất và giáo dục quốc phòng | P40: 200113501 | Q40: Bộ môn Giáo dục thể chất | R40: 3 | S40: 1 | W40: =_xlfn.XLOOKUP(B40,[2]Sheet!$C$10:$C$107,[2]Sheet!$K$10:$K$107) -> 0 | X40: =IF(W40=0,"Không",W40) -> Không
A41: 10 | B41: 71PEGO10092 | C41: Golf | E41: 2 | F41: 45 | J41: TC102 (2TC) | K41: Không | L41: Không | M41: Giáo dục thể chất và giáo dục quốc phòng | P41: 200113501 | Q41: Bộ môn Giáo dục thể chất | R41: 3 | S41: 1 | W41: =_xlfn.XLOOKUP(B41,[2]Sheet!$C$10:$C$107,[2]Sheet!$K$10:$K$107) -> 0 | X41: =IF(W41=0,"Không",W41) -> Không
A42: 11 | B42: 71PEMA10132 | C42: Võ thuật | E42: 2 | F42: 45 | J42: TC102 (2TC) | K42: Không | L42: Không | M42: Giáo dục thể chất và giáo dục quốc phòng | P42: 200113501 | Q42: Bộ môn Giáo dục thể chất | R42: 3 | S42: 1 | W42: =_xlfn.XLOOKUP(B42,[2]Sheet!$C$10:$C$107,[2]Sheet!$K$10:$K$107) -> 0 | X42: =IF(W42=0,"Không",W42) -> Không
A43: 12 | B43: 71PEMT10152 | C43: Marathon | E43: 2 | F43: 45 | J43: TC102 (2TC) | K43: Không | L43: Không | M43: Giáo dục thể chất và giáo dục quốc phòng | P43: 200113501 | Q43: Bộ môn Giáo dục thể chất | R43: 3 | S43: 1 | W43: =_xlfn.XLOOKUP(B43,[2]Sheet!$C$10:$C$107,[2]Sheet!$K$10:$K$107) -> 0 | X43: =IF(W43=0,"Không",W43) -> Không
...

Sheet MaBoMon
A1: TRƯỜNG ĐẠI HỌC VĂN LANG PHÒNG ĐÀO TẠO
A2: DANH MỤC BỘ MÔN THEO TỜ TRÌNH ĐÃ ĐƯỢC HIỆU TRƯỞNG PHÊ DUYỆT (Theo tờ trình số 01/TTr-ĐHVL-BCL, ngày 27 tháng 02 năm 2021)
A4: STT | B4: Mã Bộ môn | C4: Tên Bộ môn | D4: Mã đơn vị | E4: Tên đơn vị | F4: Ghi chú
A5: 1 | B5: 200110101 | C5: Bộ môn Kế toán quản trị | D5: 2001101 | E5: Khoa Kế toán - Kiểm toán
A6: 2 | B6: 200110102 | C6: Bộ môn Kế toán tài chính và Thực hành kế toán | D6: 2001101 | E6: Khoa Kế toán - Kiểm toán
A7: 3 | B7: 200110103 | C7: Bộ môn Nguyên lý kế toán và Kiểm toán | D7: 2001101 | E7: Khoa Kế toán - Kiểm toán
A8: 4 | B8: 200110201 | C8: Bộ môn Luật Hiến pháp - Hành chính | D8: 2001102 | E8: Khoa Luật
A9: 5 | B9: 200110202 | C9: Bộ môn Luật Quốc tế | D9: 2001102 | E9: Khoa Luật
A10: 6 | B10: 200110203 | C10: Bộ môn Luật Thương mại - Dân sự | D10: 2001102 | E10: Khoa Luật
A11: 7 | B11: 200110204 | C11: Bộ môn Luật hình sự | D11: 2001102 | E11: Khoa Luật
A12: 8 | B12: 200110301 | C12: Bộ môn Kỹ năng ngôn ngữ | D12: 2001103 | E12: Khoa Ngoại ngữ
A13: 9 | B13: 200110302 | C13: Bộ môn Ngoại ngữ 2 Và Ngôn Ngữ Trung | D13: 2001103 | E13: Khoa Ngoại ngữ
A14: 10 | B14: 200110303 | C14: Bộ môn Ngôn ngữ chuyên ngành | D14: 2001103 | E14: Khoa Ngoại ngữ
A15: 11 | B15: 200110304 | C15: Bộ môn Chương trình đào tạo đặc biệt & liên kết quốc tế | D15: 2001103 | E15: Khoa Ngoại ngữ
A16: 12 | B16: 200110401 | C16: Bộ môn Quản Trị Chất Lượng | D16: 2001104 | E16: Khoa Quản trị kinh doanh
... A97: 93 | B97: 200113301 | C97: Bộ môn Giáo dục quốc phòng và an ninh | D97: 2001133 | E97: Phòng Giáo dục Quốc phòng và An ninh
A98: 94 | B98: 200113501 | C98: Bộ môn Giáo dục thể chất | D98: 2001135 | E98: Trung tâm thể dục thể thao
E101: Cập nhật ngày 02 tháng 7 năm 2021 (Theo dữ liệu HRM cung cấp)
